Workbook

Sheet CONTROLE
A1: INIBANK | B1: INICIATIVA | C1: Tipo | D1: Prestadora | E1: Matrícula | F1: Nome | G1: Projeção 2026 | H1: 46023 | I1: 46054 | J1: 46082 | K1: 46113 | L1: 46143 | M1: 46174 | N1: 46204 | O1: 46235 | P1: 46266 | Q1: 46296 | R1: 46327 | S1: 46357
A2: INIBANK-611 | B2: Implantação do SalesForce para Central de Atendimento de Clientes PJ | C2: Forecast | G2: =SUM(H2:S2) -> 0 | H2: 0 | I2: 0 | J2: 0 | K2: 0 | L2: 0 | M2: 0 | N2: 0 | O2: 0 | P2: 0 | Q2: 0 | R2: 0 | S2: 0
A3: INIBANK-289 | B3: Sustentação Atendimento Salesforce Odin | C3: Forecast | G3: =SUM(H3:S3) -> 0 | H3: 0 | I3: 0 | J3: 0 | K3: 0 | L3: 0 | M3: 0 | N3: 0 | O3: 0 | P3: 0 | Q3: 0 | R3: 0 | S3: 0
A4: INIBANK-1417 | B4: [Sustentação] Atendimento / Salesforce | C4: Forecast | G4: =SUM(H4:S4) -> 1865718 | H4: 155476.5 | I4: 155476.5 | J4: 155476.5 | K4: 155476.5 | L4: 155476.5 | M4: 155476.5 | N4: 155476.5 | O4: 155476.5 | P4: 155476.5 | Q4: 155476.5 | R4: 155476.5 | S4: 155476.5
A5: INIBANK-1173 | B5: [Book] Squad Salesforce (Atendimento) | C5: Forecast | G5: =SUM(H5:S5) -> 3955366 | H5: =329613.833333333 -> 329613.83 | I5: 329613.83 | J5: 329613.83 | K5: 329613.83 | L5: 329613.83 | M5: 329613.83 | N5: 329613.83 | O5: 329613.83 | P5: 329613.83 | Q5: 329613.83 | R5: 329613.83 | S5: 329613.83
A6: INIBANK-1349 | B6: Atendimento INVEST BANK | C6: Forecast | G6: =SUM(H6:S6) -> 100000 | H6: 56033.94 | I6: 0 | J6: 43966.06 | K6: 0 | L6: 0 | M6: 0 | N6: 0 | O6: 0 | P6: 0 | Q6: 0 | R6: 0 | S6: 0
A8: INIBANK-1173 | B8: [Book] Squad Salesforce (Atendimento) | C8: Time Alocado | D8: Sys4B | E8: P0660057 | F8: Cleiton Lima de Jesus | G8: =SUM(H8:S8) -> 482760.96 | H8: =VLOOKUP($E8,'ORÇAMENTO 2026 v3'!$D:$X,8,0) -> 40230.08 | I8: =VLOOKUP($E8,'ORÇAMENTO 2026 v3'!$D:$X,9,0) -> 40230.08 | J8: =VLOOKUP($E8,'ORÇAMENTO 2026 v3'!$D:$X,10,0) -> 40230.08 | K8: =VLOOKUP($E8,'ORÇAMENTO 2026 v3'!$D:$X,11,0) -> 40230.08 | L8: =VLOOKUP($E8,'ORÇAMENTO 2026 v3'!$D:$X,12,0) -> 40230.08 | M8: =VLOOKUP($E8,'ORÇAMENTO 2026 v3'!$D:$X,13,0) -> 40230.08 | N8: =VLOOKUP($E8,'ORÇAMENTO 2026 v3'!$D:$X,14,0) -> 40230.08 | O8: =VLOOKUP($E8,'ORÇAMENTO 2026 v3'!$D:$X,15,0) -> 40230.08 | P8: =VLOOKUP($E8,'ORÇAMENTO 2026 v3'!$D:$X,16,0) -> 40230.08 | Q8: =VLOOKUP($E8,'ORÇAMENTO 2026 v3'!$D:$X,17,0) -> 40230.08 | R8: =VLOOKUP($E8,'ORÇAMENTO 2026 v3'!$D:$X,18,0) -> 40230.08 | S8: =VLOOKUP($E8,'ORÇAMENTO 2026 v3'!$D:$X,19,0) -> 40230.08
A9: INIBANK-1173 | B9: [Book] Squad Salesforce (Atendimento) | C9: Time Alocado | D9: Sys4B | E9: P0656797 | F9: Gustavo Seiji Onizuka | G9: =SUM(H9:S9) -> 451693.44 | H9: =VLOOKUP($E9,'ORÇAMENTO 2026 v3'!$D:$X,8,0) -> 37641.12 | I9: =VLOOKUP($E9,'ORÇAMENTO 2026 v3'!$D:$X,9,0) -> 37641.12 | J9: =VLOOKUP($E9,'ORÇAMENTO 2026 v3'!$D:$X,10,0) -> 37641.12 | K9: =VLOOKUP($E9,'ORÇAMENTO 2026 v3'!$D:$X,11,0) -> 37641.12 | L9: =VLOOKUP($E9,'ORÇAMENTO 2026 v3'!$D:$X,12,0) -> 37641.12 | M9: =VLOOKUP($E9,'ORÇAMENTO 2026 v3'!$D:$X,13,0) -> 37641.12 | N9: =VLOOKUP($E9,'ORÇAMENTO 2026 v3'!$D:$X,14,0) -> 37641.12 | O9: =VLOOKUP($E9,'ORÇAMENTO 2026 v3'!$D:$X,15,0) -> 37641.12 | P9: =VLOOKUP($E9,'ORÇAMENTO 2026 v3'!$D:$X,16,0) -> 37641.12 | Q9: =VLOOKUP($E9,'ORÇAMENTO 2026 v3'!$D:$X,17,0) -> 37641.12 | R9: =VLOOKUP($E9,'ORÇAMENTO 2026 v3'!$D:$X,18,0) -> 37641.12 | S9: =VLOOKUP($E9,'ORÇAMENTO 2026 v3'!$D:$X,19,0) -> 37641.12
A10: INIBANK-1173 | B10: [Book] Squad Salesforce (Atendimento) | C10: Time Alocado | D10: Sys4B | E10: P0658519 | F10: Leonardo Lins | G10: =SUM(H10:S10) -> 451693.44 | H10: =VLOOKUP($E10,'ORÇAMENTO 2026 v3'!$D:$X,8,0) -> 37641.12 | I10: =VLOOKUP($E10,'ORÇAMENTO 2026 v3'!$D:$X,9,0) -> 37641.12 | J10: =VLOOKUP($E10,'ORÇAMENTO 2026 v3'!$D:$X,10,0) -> 37641.12 | K10: =VLOOKUP($E10,'ORÇAMENTO 2026 v3'!$D:$X,11,0) -> 37641.12 | L10: =VLOOKUP($E10,'ORÇAMENTO 2026 v3'!$D:$X,12,0) -> 37641.12 | M10: =VLOOKUP($E10,'ORÇAMENTO 2026 v3'!$D:$X,13,0) -> 37641.12 | N10: =VLOOKUP($E10,'ORÇAMENTO 2026 v3'!$D:$X,14,0) -> 37641.12 | O10: =VLOOKUP($E10,'ORÇAMENTO 2026 v3'!$D:$X,15,0) -> 37641.12 | P10: =VLOOKUP($E10,'ORÇAMENTO 2026 v3'!$D:$X,16,0) -> 37641.12 | Q10: =VLOOKUP($E10,'ORÇAMENTO 2026 v3'!$D:$X,17,0) -> 37641.12 | R10: =VLOOKUP($E10,'ORÇAMENTO 2026 v3'!$D:$X,18,0) -> 37641.12 | S10: =VLOOKUP($E10,'ORÇAMENTO 2026 v3'!$D:$X,19,0) -> 37641.12
A11: INIBANK-1173 | B11: [Book] Squad Salesforce (Atendimento) | C11: Time Alocado | D11: Sys4B | E11: P0654694 | F11: Carlos Eduardo Santos Santana | G11: =SUM(H11:S11) -> 451693.44 | H11: =VLOOKUP($E11,'ORÇAMENTO 2026 v3'!$D:$X,8,0) -> 37641.12 | I11: =VLOOKUP($E11,'ORÇAMENTO 2026 v3'!$D:$X,9,0) -> 37641.12 | J11: =VLOOKUP($E11,'ORÇAMENTO 2026 v3'!$D:$X,10,0) -> 37641.12 | K11: =VLOOKUP($E11,'ORÇAMENTO 2026 v3'!$D:$X,11,0) -> 37641.12 | L11: =VLOOKUP($E11,'ORÇAMENTO 2026 v3'!$D:$X,12,0) -> 37641.12 | M11: =VLOOKUP($E11,'ORÇAMENTO 2026 v3'!$D:$X,13,0) -> 37641.12 | N11: =VLOOKUP($E11,'ORÇAMENTO 2026 v3'!$D:$X,14,0) -> 37641.12 | O11: =VLOOKUP($E11,'ORÇAMENTO 2026 v3'!$D:$X,15,0) -> 37641.12 | P11: =VLOOKUP($E11,'ORÇAMENTO 2026 v3'!$D:$X,16,0) -> 37641.12 | Q11: =VLOOKUP($E11,'ORÇAMENTO 2026 v3'!$D:$X,17,0) -> 37641.12 | R11: =VLOOKUP($E11,'ORÇAMENTO 2026 v3'!$D:$X,18,0) -> 37641.12 | S11: =VLOOKUP($E11,'ORÇAMENTO 2026 v3'!$D:$X,19,0) -> 37641.12
A12: INIBANK-1173 | B12: [Book] Squad Salesforce (Atendimento) | C12: Time Alocado | D12: Capgemini | E12: P0661574 | F12: Leonardo Lassance | G12: =SUM(H12:S12) -> 633093.12 | H12: =VLOOKUP($E12,'ORÇAMENTO 2026 v3'!$D:$X,8,0) -> 52757.76 | I12: =VLOOKUP($E12,'ORÇAMENTO 2026 v3'!$D:$X,9,0) -> 52757.76 | J12: =VLOOKUP($E12,'ORÇAMENTO 2026 v3'!$D:$X,10,0) -> 52757.76 | K12: =VLOOKUP($E12,'ORÇAMENTO 2026 v3'!$D:$X,11,0) -> 52757.76 | L12: =VLOOKUP($E12,'ORÇAMENTO 2026 v3'!$D:$X,12,0) -> 52757.76 | M12: =VLOOKUP($E12,'ORÇAMENTO 2026 v3'!$D:$X,13,0) -> 52757.76 | N12: =VLOOKUP($E12,'ORÇAMENTO 2026 v3'!$D:$X,14,0) -> 52757.76 | O12: =VLOOKUP($E12,'ORÇAMENTO 2026 v3'!$D:$X,15,0) -> 52757.76 | P12: =VLOOKUP($E12,'ORÇAMENTO 2026 v3'!$D:$X,16,0) -> 52757.76 | Q12: =VLOOKUP($E12,'ORÇAMENTO 2026 v3'!$D:$X,17,0) -> 52757.76 | R12: =VLOOKUP($E12,'ORÇAMENTO 2026 v3'!$D:$X,18,0) -> 52757.76 | S12: =VLOOKUP($E12,'ORÇAMENTO 2026 v3'!$D:$X,19,0) -> 52757.76
A13: INIBANK-1173 | B13: [Book] Squad Salesforce (Atendimento) | C13: Time Alocado | D13: Capgemini | E13: P0661361 | F13: Fernando da Silva Trevisan | G13: =SUM(H13:S13) -> 611107.2 | H13: =VLOOKUP($E13,'ORÇAMENTO 2026 v3'!$D:$X,8,0) -> 50925.6 | I13: =VLOOKUP($E13,'ORÇAMENTO 2026 v3'!$D:$X,9,0) -> 50925.6 | J13: =VLOOKUP($E13,'ORÇAMENTO 2026 v3'!$D:$X,10,0) -> 50925.6 | K13: =VLOOKUP($E13,'ORÇAMENTO 2026 v3'!$D:$X,11,0) -> 50925.6 | L13: =VLOOKUP($E13,'ORÇAMENTO 2026 v3'!$D:$X,12,0) -> 50925.6 | M13: =VLOOKUP($E13,'ORÇAMENTO 2026 v3'!$D:$X,13,0) -> 50925.6 | N13: =VLOOKUP($E13,'ORÇAMENTO 2026 v3'!$D:$X,14,0) -> 50925.6 | O13: =VLOOKUP($E13,'ORÇAMENTO 2026 v3'!$D:$X,15,0) -> 50925.6 | P13: =VLOOKUP($E13,'ORÇAMENTO 2026 v3'!$D:$X,16,0) -> 50925.6 | Q13: =VLOOKUP($E13,'ORÇAMENTO 2026 v3'!$D:$X,17,0) -> 50925.6 | R13: =VLOOKUP($E13,'ORÇAMENTO 2026 v3'!$D:$X,18,0) -> 50925.6 | S13: =VLOOKUP($E13,'ORÇAMENTO 2026 v3'!$D:$X,19,0) -> 50925.6
A14: INIBANK-1173 | B14: [Book] Squad Salesforce (Atendimento) | C14: Time Alocado | D14: Capgemini | E14: P0661715 | F14: Marcel Vallim Moreira | G14: =SUM(H14:S14) -> 427933.44 | H14: =VLOOKUP($E14,'ORÇAMENTO 2026 v3'!$D:$X,8,0) -> 35661.12 | I14: =VLOOKUP($E14,'ORÇAMENTO 2026 v3'!$D:$X,9,0) -> 35661.12 | J14: =VLOOKUP($E14,'ORÇAMENTO 2026 v3'!$D:$X,10,0) -> 35661.12 | K14: =VLOOKUP($E14,'ORÇAMENTO 2026 v3'!$D:$X,11,0) -> 35661.12 | L14: =VLOOKUP($E14,'ORÇAMENTO 2026 v3'!$D:$X,12,0) -> 35661.12 | M14: =VLOOKUP($E14,'ORÇAMENTO 2026 v3'!$D:$X,13,0) -> 35661.12 | N14: =VLOOKUP($E14,'ORÇAMENTO 2026 v3'!$D:$X,14,0) -> 35661.12 | O14: =VLOOKUP($E14,'ORÇAMENTO 2026 v3'!$D:$X,15,0) -> 35661.12 | P14: =VLOOKUP($E14,'ORÇAMENTO 2026 v3'!$D:$X,16,0) -> 35661.12 | Q14: =VLOOKUP($E14,'ORÇAMENTO 2026 v3'!$D:$X,17,0) -> 35661.12 | R14: =VLOOKUP($E14,'ORÇAMENTO 2026 v3'!$D:$X,18,0) -> 35661.12 | S14: =VLOOKUP($E14,'ORÇAMENTO 2026 v3'!$D:$X,19,0) -> 35661.12
A15: INIBANK-1173 | B15: [Book] Squad Salesforce (Atendimento) | C15: Time Alocado | D15: Capgemini | E15: P0661738 | F15: Erick Delfino Silva | G15: =SUM(H15:S15) -> 409178.88 | H15: =VLOOKUP($E15,'ORÇAMENTO 2026 v3'!$D:$X,8,0) -> 34098.24 | I15: =VLOOKUP($E15,'ORÇAMENTO 2026 v3'!$D:$X,9,0) -> 34098.24 | J15: =VLOOKUP($E15,'ORÇAMENTO 2026 v3'!$D:$X,10,0) -> 34098.24 | K15: =VLOOKUP($E15,'ORÇAMENTO 2026 v3'!$D:$X,11,0) -> 34098.24 | L15: =VLOOKUP($E15,'ORÇAMENTO 2026 v3'!$D:$X,12,0) -> 34098.24 | M15: =VLOOKUP($E15,'ORÇAMENTO 2026 v3'!$D:$X,13,0) -> 34098.24 | N15: =VLOOKUP($E15,'ORÇAMENTO 2026 v3'!$D:$X,14,0) -> 34098.24 | O15: =VLOOKUP($E15,'ORÇAMENTO 2026 v3'!$D:$X,15,0) -> 34098.24 | P15: =VLOOKUP($E15,'ORÇAMENTO 2026 v3'!$D:$X,16,0) -> 34098.24 | Q15: =VLOOKUP($E15,'ORÇAMENTO 2026 v3'!$D:$X,17,0) -> 34098.24 | R15: =VLOOKUP($E15,'ORÇAMENTO 2026 v3'!$D:$X,18,0) -> 34098.24 | S15: =VLOOKUP($E15,'ORÇAMENTO 2026 v3'!$D:$X,19,0) -> 34098.24
A16: INIBANK-1417 | B16: [Sustentação] Atendimento / Salesforce | C16: Time Alocado | D16: Sys4B | E16: P0662312 | F16: Francielle Thiezo Revesso Pinto | G16: =SUM(H16:S16) -> 451693.44 | H16: =VLOOKUP($E16,'ORÇAMENTO 2026 v3'!$D:$X,8,0) -> 37641.12 | I16: =VLOOKUP($E16,'ORÇAMENTO 2026 v3'!$D:$X,9,0) -> 37641.12 | J16: =VLOOKUP($E16,'ORÇAMENTO 2026 v3'!$D:$X,10,0) -> 37641.12 | K16: =VLOOKUP($E16,'ORÇAMENTO 2026 v3'!$D:$X,11,0) -> 37641.12 | L16: =VLOOKUP($E16,'ORÇAMENTO 2026 v3'!$D:$X,12,0) -> 37641.12 | M16: =VLOOKUP($E16,'ORÇAMENTO 2026 v3'!$D:$X,13,0) -> 37641.12 | N16: =VLOOKUP($E16,'ORÇAMENTO 2026 v3'!$D:$X,14,0) -> 37641.12 | O16: =VLOOKUP($E16,'ORÇAMENTO 2026 v3'!$D:$X,15,0) -> 37641.12 | P16: =VLOOKUP($E16,'ORÇAMENTO 2026 v3'!$D:$X,16,0) -> 37641.12 | Q16: =VLOOKUP($E16,'ORÇAMENTO 2026 v3'!$D:$X,17,0) -> 37641.12 | R16: =VLOOKUP($E16,'ORÇAMENTO 2026 v3'!$D:$X,18,0) -> 37641.12 | S16: =VLOOKUP($E16,'ORÇAMENTO 2026 v3'!$D:$X,19,0) -> 37641.12
A17: INIBANK-1417 | B17: [Sustentação] Atendimento / Salesforce | C17: Time Alocado | D17: Sys4B | E17: P0650648 | F17: Lucas Takita | G17: =SUM(H17:S17) -> 451693.44 | H17: =VLOOKUP($E17,'ORÇAMENTO 2026 v3'!$D:$X,8,0) -> 37641.12 | I17: =VLOOKUP($E17,'ORÇAMENTO 2026 v3'!$D:$X,9,0) -> 37641.12 | J17: =VLOOKUP($E17,'ORÇAMENTO 2026 v3'!$D:$X,10,0) -> 37641.12 | K17: =VLOOKUP($E17,'ORÇAMENTO 2026 v3'!$D:$X,11,0) -> 37641.12 | L17: =VLOOKUP($E17,'ORÇAMENTO 2026 v3'!$D:$X,12,0) -> 37641.12 | M17: =VLOOKUP($E17,'ORÇAMENTO 2026 v3'!$D:$X,13,0) -> 37641.12 | N17: =VLOOKUP($E17,'ORÇAMENTO 2026 v3'!$D:$X,14,0) -> 37641.12 | O17: =VLOOKUP($E17,'ORÇAMENTO 2026 v3'!$D:$X,15,0) -> 37641.12 | P17: =VLOOKUP($E17,'ORÇAMENTO 2026 v3'!$D:$X,16,0) -> 37641.12 | Q17: =VLOOKUP($E17,'ORÇAMENTO 2026 v3'!$D:$X,17,0) -> 37641.12 | R17: =VLOOKUP($E17,'ORÇAMENTO 2026 v3'!$D:$X,18,0) -> 37641.12 | S17: =VLOOKUP($E17,'ORÇAMENTO 2026 v3'!$D:$X,19,0) -> 37641.12
A18: INIBANK-1417 | B18: [Sustentação] Atendimento / Salesforce | C18: Time Alocado | D18: Sys4B | E18: P0663654 | F18: Gabriel Costa Datovo Inoue Maekawa | G18: =SUM(H18:S18) -> 404152.32 | H18: =VLOOKUP($E18,'ORÇAMENTO 2026 v3'!$D:$X,8,0) -> 33679.36 | I18: =VLOOKUP($E18,'ORÇAMENTO 2026 v3'!$D:$X,9,0) -> 33679.36 | J18: =VLOOKUP($E18,'ORÇAMENTO 2026 v3'!$D:$X,10,0) -> 33679.36 | K18: =VLOOKUP($E18,'ORÇAMENTO 2026 v3'!$D:$X,11,0) -> 33679.36 | L18: =VLOOKUP($E18,'ORÇAMENTO 2026 v3'!$D:$X,12,0) -> 33679.36 | M18: =VLOOKUP($E18,'ORÇAMENTO 2026 v3'!$D:$X,13,0) -> 33679.36 | N18: =VLOOKUP($E18,'ORÇAMENTO 2026 v3'!$D:$X,14,0) -> 33679.36 | O18: =VLOOKUP($E18,'ORÇAMENTO 2026 v3'!$D:$X,15,0) -> 33679.36 | P18: =VLOOKUP($E18,'ORÇAMENTO 2026 v3'!$D:$X,16,0) -> 33679.36 | Q18: =VLOOKUP($E18,'ORÇAMENTO 2026 v3'!$D:$X,17,0) -> 33679.36 | R18: =VLOOKUP($E18,'ORÇAMENTO 2026 v3'!$D:$X,18,0) -> 33679.36 | S18: =VLOOKUP($E18,'ORÇAMENTO 2026 v3'!$D:$X,19,0) -> 33679.36
A19: INIBANK-1417 | B19: [Sustentação] Atendimento / Salesforce | C19: Time Alocado | D19: Sys4B | E19: P0000000 | F19: Plantão Salesforce Odin | G19: =SUM(H19:S19) -> 480000 | H19: =VLOOKUP($E19,'ORÇAMENTO 2026 v3'!$D:$X,8,0) -> 40000 | I19: =VLOOKUP($E19,'ORÇAMENTO 2026 v3'!$D:$X,9,0) -> 40000 | J19: =VLOOKUP($E19,'ORÇAMENTO 2026 v3'!$D:$X,10,0) -> 40000 | K19: =VLOOKUP($E19,'ORÇAMENTO 2026 v3'!$D:$X,11,0) -> 40000 | L19: =VLOOKUP($E19,'ORÇAMENTO 2026 v3'!$D:$X,12,0) -> 40000 | M19: =VLOOKUP($E19,'ORÇAMENTO 2026 v3'!$D:$X,13,0) -> 40000 | N19: =VLOOKUP($E19,'ORÇAMENTO 2026 v3'!$D:$X,14,0) -> 40000 | O19: =VLOOKUP($E19,'ORÇAMENTO 2026 v3'!$D:$X,15,0) -> 40000 | P19: =VLOOKUP($E19,'ORÇAMENTO 2026 v3'!$D:$X,16,0) -> 40000 | Q19: =VLOOKUP($E19,'ORÇAMENTO 2026 v3'!$D:$X,17,0) -> 40000 | R19: =VLOOKUP($E19,'ORÇAMENTO 2026 v3'!$D:$X,18,0) -> 40000 | S19: =VLOOKUP($E19,'ORÇAMENTO 2026 v3'!$D:$X,19,0) -> 40000
A21: INIBANK-611 | B21: Implantação do SalesForce para Central de Atendimento de Clientes PJ | C21: Realizado | G21: =SUM(H21:S21) -> 252716.37 | H21: =SUMIFS(NOTA_FISCAL_ANALITICO!$G:$G,NOTA_FISCAL_ANALITICO!$D:$D,CONTROLE!H$1,NOTA_FISCAL_ANALITICO!$J:$J,CONTROLE!$A21) -> 252716.37 | I21: =SUMIFS(NOTA_FISCAL_ANALITICO!$G:$G,NOTA_FISCAL_ANALITICO!$D:$D,CONTROLE!I$1,NOTA_FISCAL_ANALITICO!$J:$J,CONTROLE!$A21) -> 0 | J21: =SUMIFS(NOTA_FISCAL_ANALITICO!$G:$G,NOTA_FISCAL_ANALITICO!$D:$D,CONTROLE!J$1,NOTA_FISCAL_ANALITICO!$J:$J,CONTROLE!$A21) -> 0 | K21: =SUMIFS(NOTA_FISCAL_ANALITICO!$G:$G,NOTA_FISCAL_ANALITICO!$D:$D,CONTROLE!K$1,NOTA_FISCAL_ANALITICO!$J:$J,CONTROLE!$A21) -> 0 | L21: =SUMIFS(NOTA_FISCAL_ANALITICO!$G:$G,NOTA_FISCAL_ANALITICO!$D:$D,CONTROLE!L$1,NOTA_FISCAL_ANALITICO!$J:$J,CONTROLE!$A21) -> 0 | M21: =SUMIFS(NOTA_FISCAL_ANALITICO!$G:$G,NOTA_FISCAL_ANALITICO!$D:$D,CONTROLE!M$1,NOTA_FISCAL_ANALITICO!$J:$J,CONTROLE!$A21) -> 0 | N21: =SUMIFS(NOTA_FISCAL_ANALITICO!$G:$G,NOTA_FISCAL_ANALITICO!$D:$D,CONTROLE!N$1,NOTA_FISCAL_ANALITICO!$J:$J,CONTROLE!$A21) -> 0 | O21: =SUMIFS(NOTA_FISCAL_ANALITICO!$G:$G,NOTA_FISCAL_ANALITICO!$D:$D,CONTROLE!O$1,NOTA_FISCAL_ANALITICO!$J:$J,CONTROLE!$A21) -> 0 | ... S21: =SUMIFS(NOTA_FISCAL_ANALITICO!$G:$G,NOTA_FISCAL_ANALITICO!$D:$D,CONTROLE!S$1,NOTA_FISCAL_ANALITICO!$J:$J,CONTROLE!$A21) -> 0
A22: INIBANK-289 | B22: Sustentação Atendimento Salesforce Odin | C22: Realizado | G22: =SUM(H22:S22) -> 0 | H22: =SUMIFS(NOTA_FISCAL_ANALITICO!$G:$G,NOTA_FISCAL_ANALITICO!$D:$D,CONTROLE!H$1,NOTA_FISCAL_ANALITICO!$J:$J,CONTROLE!$A22) -> 0 | I22: =SUMIFS(NOTA_FISCAL_ANALITICO!$G:$G,NOTA_FISCAL_ANALITICO!$D:$D,CONTROLE!I$1,NOTA_FISCAL_ANALITICO!$J:$J,CONTROLE!$A22) -> 0 | J22: =SUMIFS(NOTA_FISCAL_ANALITICO!$G:$G,NOTA_FISCAL_ANALITICO!$D:$D,CONTROLE!J$1,NOTA_FISCAL_ANALITICO!$J:$J,CONTROLE!$A22) -> 0 | K22: =SUMIFS(NOTA_FISCAL_ANALITICO!$G:$G,NOTA_FISCAL_ANALITICO!$D:$D,CONTROLE!K$1,NOTA_FISCAL_ANALITICO!$J:$J,CONTROLE!$A22) -> 0 | L22: =SUMIFS(NOTA_FISCAL_ANALITICO!$G:$G,NOTA_FISCAL_ANALITICO!$D:$D,CONTROLE!L$1,NOTA_FISCAL_ANALITICO!$J:$J,CONTROLE!$A22) -> 0 | M22: =SUMIFS(NOTA_FISCAL_ANALITICO!$G:$G,NOTA_FISCAL_ANALITICO!$D:$D,CONTROLE!M$1,NOTA_FISCAL_ANALITICO!$J:$J,CONTROLE!$A22) -> 0 | N22: =SUMIFS(NOTA_FISCAL_ANALITICO!$G:$G,NOTA_FISCAL_ANALITICO!$D:$D,CONTROLE!N$1,NOTA_FISCAL_ANALITICO!$J:$J,CONTROLE!$A22) -> 0 | O22: =SUMIFS(NOTA_FISCAL_ANALITICO!$G:$G,NOTA_FISCAL_ANALITICO!$D:$D,CONTROLE!O$1,NOTA_FISCAL_ANALITICO!$J:$J,CONTROLE!$A22) -> 0 | ... S22: =SUMIFS(NOTA_FISCAL_ANALITICO!$G:$G,NOTA_FISCAL_ANALITICO!$D:$D,CONTROLE!S$1,NOTA_FISCAL_ANALITICO!$J:$J,CONTROLE!$A22) -> 0
A23: INIBANK-1417 | B23: [Sustentação] Atendimento / Salesforce | C23: Realizado | G23: =SUM(H23:S23) -> 245176.79 | H23: =SUMIFS(NOTA_FISCAL_ANALITICO!$G:$G,NOTA_FISCAL_ANALITICO!$D:$D,CONTROLE!H$1,NOTA_FISCAL_ANALITICO!$J:$J,CONTROLE!$A23) -> 118699.28 | I23: =SUMIFS(NOTA_FISCAL_ANALITICO!$G:$G,NOTA_FISCAL_ANALITICO!$D:$D,CONTROLE!I$1,NOTA_FISCAL_ANALITICO!$J:$J,CONTROLE!$A23) -> 126477.51 | J23: =SUMIFS(NOTA_FISCAL_ANALITICO!$G:$G,NOTA_FISCAL_ANALITICO!$D:$D,CONTROLE!J$1,NOTA_FISCAL_ANALITICO!$J:$J,CONTROLE!$A23) -> 0 | K23: =SUMIFS(NOTA_FISCAL_ANALITICO!$G:$G,NOTA_FISCAL_ANALITICO!$D:$D,CONTROLE!K$1,NOTA_FISCAL_ANALITICO!$J:$J,CONTROLE!$A23) -> 0 | L23: =SUMIFS(NOTA_FISCAL_ANALITICO!$G:$G,NOTA_FISCAL_ANALITICO!$D:$D,CONTROLE!L$1,NOTA_FISCAL_ANALITICO!$J:$J,CONTROLE!$A23) -> 0 | M23: =SUMIFS(NOTA_FISCAL_ANALITICO!$G:$G,NOTA_FISCAL_ANALITICO!$D:$D,CONTROLE!M$1,NOTA_FISCAL_ANALITICO!$J:$J,CONTROLE!$A23) -> 0 | N23: =SUMIFS(NOTA_FISCAL_ANALITICO!$G:$G,NOTA_FISCAL_ANALITICO!$D:$D,CONTROLE!N$1,NOTA_FISCAL_ANALITICO!$J:$J,CONTROLE!$A23) -> 0 | O23: =SUMIFS(NOTA_FISCAL_ANALITICO!$G:$G,NOTA_FISCAL_ANALITICO!$D:$D,CONTROLE!O$1,NOTA_FISCAL_ANALITICO!$J:$J,CONTROLE!$A23) -> 0 | ... S23: =SUMIFS(NOTA_FISCAL_ANALITICO!$G:$G,NOTA_FISCAL_ANALITICO!$D:$D,CONTROLE!S$1,NOTA_FISCAL_ANALITICO!$J:$J,CONTROLE!$A23) -> 0
A24: INIBANK-1173 | B24: [Book] Squad Salesforce (Atendimento) | C24: Realizado | G24: =SUM(H24:S24) -> 451723.18 | H24: =SUMIFS(NOTA_FISCAL_ANALITICO!$G:$G,NOTA_FISCAL_ANALITICO!$D:$D,CONTROLE!H$1,NOTA_FISCAL_ANALITICO!$J:$J,CONTROLE!$A24) -> 155501.04 | I24: =SUMIFS(NOTA_FISCAL_ANALITICO!$G:$G,NOTA_FISCAL_ANALITICO!$D:$D,CONTROLE!I$1,NOTA_FISCAL_ANALITICO!$J:$J,CONTROLE!$A24) -> 296222.14 | J24: =SUMIFS(NOTA_FISCAL_ANALITICO!$G:$G,NOTA_FISCAL_ANALITICO!$D:$D,CONTROLE!J$1,NOTA_FISCAL_ANALITICO!$J:$J,CONTROLE!$A24) -> 0 | K24: =SUMIFS(NOTA_FISCAL_ANALITICO!$G:$G,NOTA_FISCAL_ANALITICO!$D:$D,CONTROLE!K$1,NOTA_FISCAL_ANALITICO!$J:$J,CONTROLE!$A24) -> 0 | L24: =SUMIFS(NOTA_FISCAL_ANALITICO!$G:$G,NOTA_FISCAL_ANALITICO!$D:$D,CONTROLE!L$1,NOTA_FISCAL_ANALITICO!$J:$J,CONTROLE!$A24) -> 0 | M24: =SUMIFS(NOTA_FISCAL_ANALITICO!$G:$G,NOTA_FISCAL_ANALITICO!$D:$D,CONTROLE!M$1,NOTA_FISCAL_ANALITICO!$J:$J,CONTROLE!$A24) -> 0 | N24: =SUMIFS(NOTA_FISCAL_ANALITICO!$G:$G,NOTA_FISCAL_ANALITICO!$D:$D,CONTROLE!N$1,NOTA_FISCAL_ANALITICO!$J:$J,CONTROLE!$A24) -> 0 | O24: =SUMIFS(NOTA_FISCAL_ANALITICO!$G:$G,NOTA_FISCAL_ANALITICO!$D:$D,CONTROLE!O$1,NOTA_FISCAL_ANALITICO!$J:$J,CONTROLE!$A24) -> 0 | ... S24: =SUMIFS(NOTA_FISCAL_ANALITICO!$G:$G,NOTA_FISCAL_ANALITICO!$D:$D,CONTROLE!S$1,NOTA_FISCAL_ANALITICO!$J:$J,CONTROLE!$A24) -> 0
A25: INIBANK-1349 | B25: Atendimento INVEST BANK | C25: Realizado | G25: =SUM(H25:S25) -> 56033.94 | H25: =SUMIFS(NOTA_FISCAL_ANALITICO!$G:$G,NOTA_FISCAL_ANALITICO!$D:$D,CONTROLE!H$1,NOTA_FISCAL_ANALITICO!$J:$J,CONTROLE!$A25) -> 56033.94 | I25: =SUMIFS(NOTA_FISCAL_ANALITICO!$G:$G,NOTA_FISCAL_ANALITICO!$D:$D,CONTROLE!I$1,NOTA_FISCAL_ANALITICO!$J:$J,CONTROLE!$A25) -> 0 | J25: =SUMIFS(NOTA_FISCAL_ANALITICO!$G:$G,NOTA_FISCAL_ANALITICO!$D:$D,CONTROLE!J$1,NOTA_FISCAL_ANALITICO!$J:$J,CONTROLE!$A25) -> 0 | K25: =SUMIFS(NOTA_FISCAL_ANALITICO!$G:$G,NOTA_FISCAL_ANALITICO!$D:$D,CONTROLE!K$1,NOTA_FISCAL_ANALITICO!$J:$J,CONTROLE!$A25) -> 0 | L25: =SUMIFS(NOTA_FISCAL_ANALITICO!$G:$G,NOTA_FISCAL_ANALITICO!$D:$D,CONTROLE!L$1,NOTA_FISCAL_ANALITICO!$J:$J,CONTROLE!$A25) -> 0 | M25: =SUMIFS(NOTA_FISCAL_ANALITICO!$G:$G,NOTA_FISCAL_ANALITICO!$D:$D,CONTROLE!M$1,NOTA_FISCAL_ANALITICO!$J:$J,CONTROLE!$A25) -> 0 | N25: =SUMIFS(NOTA_FISCAL_ANALITICO!$G:$G,NOTA_FISCAL_ANALITICO!$D:$D,CONTROLE!N$1,NOTA_FISCAL_ANALITICO!$J:$J,CONTROLE!$A25) -> 0 | O25: =SUMIFS(NOTA_FISCAL_ANALITICO!$G:$G,NOTA_FISCAL_ANALITICO!$D:$D,CONTROLE!O$1,NOTA_FISCAL_ANALITICO!$J:$J,CONTROLE!$A25) -> 0 | ... S25: =SUMIFS(NOTA_FISCAL_ANALITICO!$G:$G,NOTA_FISCAL_ANALITICO!$D:$D,CONTROLE!S$1,NOTA_FISCAL_ANALITICO!$J:$J,CONTROLE!$A25) -> 0
A27: INIBANK-611 | B27: Implantação do SalesForce para Central de Atendimento de Clientes PJ | C27: Resultado | G27: =SUM(H27:S27) -> -252716.37 | H27: =SUMIFS(H$2:H$26,$C$2:$C$26,"Forecast",$A$2:$A$26,$A27)-SUMIFS(H$2:H$26,$C$2:$C$26,"Realizado",$A$2:$A$26,$A27) -> -252716.37 | I27: =SUMIFS(I$2:I$26,$C$2:$C$26,"Forecast",$A$2:$A$26,$A27)-SUMIFS(I$2:I$26,$C$2:$C$26,"Realizado",$A$2:$A$26,$A27) -> 0 | J27: =SUMIFS(J$2:J$26,$C$2:$C$26,"Forecast",$A$2:$A$26,$A27)-SUMIFS(J$2:J$26,$C$2:$C$26,"Realizado",$A$2:$A$26,$A27) -> 0 | K27: =SUMIFS(K$2:K$26,$C$2:$C$26,"Forecast",$A$2:$A$26,$A27)-SUMIFS(K$2:K$26,$C$2:$C$26,"Realizado",$A$2:$A$26,$A27) -> 0 | L27: =SUMIFS(L$2:L$26,$C$2:$C$26,"Forecast",$A$2:$A$26,$A27)-SUMIFS(L$2:L$26,$C$2:$C$26,"Realizado",$A$2:$A$26,$A27) -> 0 | M27: =SUMIFS(M$2:M$26,$C$2:$C$26,"Forecast",$A$2:$A$26,$A27)-SUMIFS(M$2:M$26,$C$2:$C$26,"Realizado",$A$2:$A$26,$A27) -> 0 | N27: =SUMIFS(N$2:N$26,$C$2:$C$26,"Forecast",$A$2:$A$26,$A27)-SUMIFS(N$2:N$26,$C$2:$C$26,"Realizado",$A$2:$A$26,$A27) -> 0 | O27: =SUMIFS(O$2:O$26,$C$2:$C$26,"Forecast",$A$2:$A$26,$A27)-SUMIFS(O$2:O$26,$C$2:$C$26,"Realizado",$A$2:$A$26,$A27) -> 0 | ... S27: =SUMIFS(S$2:S$26,$C$2:$C$26,"Forecast",$A$2:$A$26,$A27)-SUMIFS(S$2:S$26,$C$2:$C$26,"Realizado",$A$2:$A$26,$A27) -> 0
A28: INIBANK-289 | B28: Sustentação Atendimento Salesforce Odin | C28: Resultado | G28: =SUM(H28:S28) -> 0 | H28: =SUMIFS(H$2:H$26,$C$2:$C$26,"Forecast",$A$2:$A$26,$A28)-SUMIFS(H$2:H$26,$C$2:$C$26,"Realizado",$A$2:$A$26,$A28) -> 0 | I28: =SUMIFS(I$2:I$26,$C$2:$C$26,"Forecast",$A$2:$A$26,$A28)-SUMIFS(I$2:I$26,$C$2:$C$26,"Realizado",$A$2:$A$26,$A28) -> 0 | J28: =SUMIFS(J$2:J$26,$C$2:$C$26,"Forecast",$A$2:$A$26,$A28)-SUMIFS(J$2:J$26,$C$2:$C$26,"Realizado",$A$2:$A$26,$A28) -> 0 | K28: =SUMIFS(K$2:K$26,$C$2:$C$26,"Forecast",$A$2:$A$26,$A28)-SUMIFS(K$2:K$26,$C$2:$C$26,"Realizado",$A$2:$A$26,$A28) -> 0 | L28: =SUMIFS(L$2:L$26,$C$2:$C$26,"Forecast",$A$2:$A$26,$A28)-SUMIFS(L$2:L$26,$C$2:$C$26,"Realizado",$A$2:$A$26,$A28) -> 0 | M28: =SUMIFS(M$2:M$26,$C$2:$C$26,"Forecast",$A$2:$A$26,$A28)-SUMIFS(M$2:M$26,$C$2:$C$26,"Realizado",$A$2:$A$26,$A28) -> 0 | N28: =SUMIFS(N$2:N$26,$C$2:$C$26,"Forecast",$A$2:$A$26,$A28)-SUMIFS(N$2:N$26,$C$2:$C$26,"Realizado",$A$2:$A$26,$A28) -> 0 | O28: =SUMIFS(O$2:O$26,$C$2:$C$26,"Forecast",$A$2:$A$26,$A28)-SUMIFS(O$2:O$26,$C$2:$C$26,"Realizado",$A$2:$A$26,$A28) -> 0 | ... S28: =SUMIFS(S$2:S$26,$C$2:$C$26,"Forecast",$A$2:$A$26,$A28)-SUMIFS(S$2:S$26,$C$2:$C$26,"Realizado",$A$2:$A$26,$A28) -> 0
A29: INIBANK-1417 | B29: [Sustentação] Atendimento / Salesforce | C29: Resultado | G29: =SUM(H29:S29) -> 1620541.2 | H29: =SUMIFS(H$2:H$26,$C$2:$C$26,"Forecast",$A$2:$A$26,$A29)-SUMIFS(H$2:H$26,$C$2:$C$26,"Realizado",$A$2:$A$26,$A29) -> 36777.22 | I29: =SUMIFS(I$2:I$26,$C$2:$C$26,"Forecast",$A$2:$A$26,$A29)-SUMIFS(I$2:I$26,$C$2:$C$26,"Realizado",$A$2:$A$26,$A29) -> 28998.99 | J29: =SUMIFS(J$2:J$26,$C$2:$C$26,"Forecast",$A$2:$A$26,$A29)-SUMIFS(J$2:J$26,$C$2:$C$26,"Realizado",$A$2:$A$26,$A29) -> 155476.5 | K29: =SUMIFS(K$2:K$26,$C$2:$C$26,"Forecast",$A$2:$A$26,$A29)-SUMIFS(K$2:K$26,$C$2:$C$26,"Realizado",$A$2:$A$26,$A29) -> 155476.5 | L29: =SUMIFS(L$2:L$26,$C$2:$C$26,"Forecast",$A$2:$A$26,$A29)-SUMIFS(L$2:L$26,$C$2:$C$26,"Realizado",$A$2:$A$26,$A29) -> 155476.5 | M29: =SUMIFS(M$2:M$26,$C$2:$C$26,"Forecast",$A$2:$A$26,$A29)-SUMIFS(M$2:M$26,$C$2:$C$26,"Realizado",$A$2:$A$26,$A29) -> 155476.5 | N29: =SUMIFS(N$2:N$26,$C$2:$C$26,"Forecast",$A$2:$A$26,$A29)-SUMIFS(N$2:N$26,$C$2:$C$26,"Realizado",$A$2:$A$26,$A29) -> 155476.5 | O29: =SUMIFS(O$2:O$26,$C$2:$C$26,"Forecast",$A$2:$A$26,$A29)-SUMIFS(O$2:O$26,$C$2:$C$26,"Realizado",$A$2:$A$26,$A29) -> 155476.5 | ... S29: =SUMIFS(S$2:S$26,$C$2:$C$26,"Forecast",$A$2:$A$26,$A29)-SUMIFS(S$2:S$26,$C$2:$C$26,"Realizado",$A$2:$A$26,$A29) -> 155476.5
A30: INIBANK-1173 | B30: [Book] Squad Salesforce (Atendimento) | C30: Resultado | G30: =SUM(H30:S30) -> 3503642.8 | H30: =SUMIFS(H$2:H$26,$C$2:$C$26,"Forecast",$A$2:$A$26,$A30)-SUMIFS(H$2:H$26,$C$2:$C$26,"Realizado",$A$2:$A$26,$A30) -> 174112.79 | I30: =SUMIFS(I$2:I$26,$C$2:$C$26,"Forecast",$A$2:$A$26,$A30)-SUMIFS(I$2:I$26,$C$2:$C$26,"Realizado",$A$2:$A$26,$A30) -> 33391.693 | J30: =SUMIFS(J$2:J$26,$C$2:$C$26,"Forecast",$A$2:$A$26,$A30)-SUMIFS(J$2:J$26,$C$2:$C$26,"Realizado",$A$2:$A$26,$A30) -> 329613.83 | K30: =SUMIFS(K$2:K$26,$C$2:$C$26,"Forecast",$A$2:$A$26,$A30)-SUMIFS(K$2:K$26,$C$2:$C$26,"Realizado",$A$2:$A$26,$A30) -> 329613.83 | L30: =SUMIFS(L$2:L$26,$C$2:$C$26,"Forecast",$A$2:$A$26,$A30)-SUMIFS(L$2:L$26,$C$2:$C$26,"Realizado",$A$2:$A$26,$A30) -> 329613.83 | M30: =SUMIFS(M$2:M$26,$C$2:$C$26,"Forecast",$A$2:$A$26,$A30)-SUMIFS(M$2:M$26,$C$2:$C$26,"Realizado",$A$2:$A$26,$A30) -> 329613.83 | N30: =SUMIFS(N$2:N$26,$C$2:$C$26,"Forecast",$A$2:$A$26,$A30)-SUMIFS(N$2:N$26,$C$2:$C$26,"Realizado",$A$2:$A$26,$A30) -> 329613.83 | O30: =SUMIFS(O$2:O$26,$C$2:$C$26,"Forecast",$A$2:$A$26,$A30)-SUMIFS(O$2:O$26,$C$2:$C$26,"Realizado",$A$2:$A$26,$A30) -> 329613.83 | ... S30: =SUMIFS(S$2:S$26,$C$2:$C$26,"Forecast",$A$2:$A$26,$A30)-SUMIFS(S$2:S$26,$C$2:$C$26,"Realizado",$A$2:$A$26,$A30) -> 329613.83
A31: INIBANK-1349 | B31: Atendimento INVEST BANK | C31: Resultado | G31: =SUM(H31:S31) -> 43966.06 | H31: =SUMIFS(H$2:H$26,$C$2:$C$26,"Forecast",$A$2:$A$26,$A31)-SUMIFS(H$2:H$26,$C$2:$C$26,"Realizado",$A$2:$A$26,$A31) -> 0 | I31: =SUMIFS(I$2:I$26,$C$2:$C$26,"Forecast",$A$2:$A$26,$A31)-SUMIFS(I$2:I$26,$C$2:$C$26,"Realizado",$A$2:$A$26,$A31) -> 0 | J31: =SUMIFS(J$2:J$26,$C$2:$C$26,"Forecast",$A$2:$A$26,$A31)-SUMIFS(J$2:J$26,$C$2:$C$26,"Realizado",$A$2:$A$26,$A31) -> 43966.06 | K31: =SUMIFS(K$2:K$26,$C$2:$C$26,"Forecast",$A$2:$A$26,$A31)-SUMIFS(K$2:K$26,$C$2:$C$26,"Realizado",$A$2:$A$26,$A31) -> 0 | L31: =SUMIFS(L$2:L$26,$C$2:$C$26,"Forecast",$A$2:$A$26,$A31)-SUMIFS(L$2:L$26,$C$2:$C$26,"Realizado",$A$2:$A$26,$A31) -> 0 | M31: =SUMIFS(M$2:M$26,$C$2:$C$26,"Forecast",$A$2:$A$26,$A31)-SUMIFS(M$2:M$26,$C$2:$C$26,"Realizado",$A$2:$A$26,$A31) -> 0 | N31: =SUMIFS(N$2:N$26,$C$2:$C$26,"Forecast",$A$2:$A$26,$A31)-SUMIFS(N$2:N$26,$C$2:$C$26,"Realizado",$A$2:$A$26,$A31) -> 0 | O31: =SUMIFS(O$2:O$26,$C$2:$C$26,"Forecast",$A$2:$A$26,$A31)-SUMIFS(O$2:O$26,$C$2:$C$26,"Realizado",$A$2:$A$26,$A31) -> 0 | ... S31: =SUMIFS(S$2:S$26,$C$2:$C$26,"Forecast",$A$2:$A$26,$A31)-SUMIFS(S$2:S$26,$C$2:$C$26,"Realizado",$A$2:$A$26,$A31) -> 0
A33: INIBANK-611 | B33: Implantação do SalesForce para Central de Atendimento de Clientes PJ | C33: Forecast Ajustado | G33: =G27 -> -252716.37 | H33: 0 | I33: 0 | J33: 0 | K33: 0 | L33: 0 | M33: 0 | N33: 0 | O33: 0 | P33: 0 | Q33: 0 | R33: 0 | S33: 0
A34: INIBANK-289 | B34: Sustentação Atendimento Salesforce Odin | C34: Forecast Ajustado | G34: =G28 -> 0 | H34: 0 | I34: 0 | J34: 0 | K34: 0 | L34: 0 | M34: 0 | N34: 0 | O34: 0 | P34: 0 | Q34: 0 | R34: 0 | S34: 0
A35: INIBANK-1417 | B35: [Sustentação] Atendimento / Salesforce | C35: Forecast Ajustado | G35: =G29 -> 1620541.2 | H35: 0 | I35: 0 | J35: =$G35/10 -> 162054.12 | K35: =$G35/10 -> 162054.12 | L35: =$G35/10 -> 162054.12 | M35: =$G35/10 -> 162054.12 | N35: =$G35/10 -> 162054.12 | O35: =$G35/10 -> 162054.12 | P35: =$G35/10 -> 162054.12 | Q35: =$G35/10 -> 162054.12 | ... S35: =$G35/10 -> 162054.12
A36: INIBANK-1173 | B36: [Book] Squad Salesforce (Atendimento) | C36: Forecast Ajustado | G36: =G30 -> 3503642.8 | H36: 0 | I36: 0 | J36: =$G36/10 -> 350364.28 | K36: =$G36/10 -> 350364.28 | L36: =$G36/10 -> 350364.28 | M36: =$G36/10 -> 350364.28 | N36: =$G36/10 -> 350364.28 | O36: =$G36/10 -> 350364.28 | P36: =$G36/10 -> 350364.28 | Q36: =$G36/10 -> 350364.28 | ... S36: =$G36/10 -> 350364.28
A37: INIBANK-1349 | B37: Atendimento INVEST BANK | C37: Forecast Ajustado | G37: =G31 -> 43966.06 | H37: 0 | I37: 0 | J37: =$G37/10 -> 4396.606 | K37: =$G37/10 -> 4396.606 | L37: =$G37/10 -> 4396.606 | M37: =$G37/10 -> 4396.606 | N37: =$G37/10 -> 4396.606 | O37: =$G37/10 -> 4396.606 | P37: =$G37/10 -> 4396.606 | Q37: =$G37/10 -> 4396.606 | ... S37: =$G37/10 -> 4396.606

Sheet FORNECEDOR
A1: CNPJ_PRESTADOR | B1: RAZAO_SOCIAL | C1: NOME_FANTASIA
A2: 65.599.953/0001-63 | B2: CAPGEMINI BRASIL LTDA | C2: Capgemini
A3: 00.607.819/0003-83 | B3: CWI SOFTWARE LTDA | C3: CWI
A4: 07.174.743/0001-27 | B4: GFT BRASIL CONSULTORIA INFORMÁTICA LTDA | C4: GFT Brasil
A5: 93.655.173/0006-33 | B5: META SERVICOS EM INFORMATICA S/A | C5: Meta
A6: 06.029.766/0004-28 | B6: OSF DIGITAL LTDA | C6: OSF Digital
A7: 24.231.517/0001-50 | B7: SYS4B INFORMATICA LTDA | C7: Sys4B

Sheet NOTA_FISCAL
A1: STATUS_NFE | B1: CNPJ_PRESTADOR | C1: RAZAO_SOCIAL | D1: NOME_FANTASIA | E1: CNPJ_TOMADOR | F1: COMPETENCIA | G1: NFE | H1: DATA_EMISSAO | I1: TOTAL_NFE | J1: APURACAO | K1: DATA_VENCIMENTO | L1: INICIATIVA | M1: INICIATIVA_DESCRICAO
A2: Autorizada | B2: 24.231.517/0001-50 | C2: SYS4B INFORMATICA LTDA | D2: Sys4B | E2: 61.198.164/0001-60 | F2: 45658 | G2: 2701 | H2: 45699 | I2: 191611.98 | J2: 22/12/24 a 21/01/25 | K2: 45759 | L2: INIBANK-54 | M2: Evoluções Salesforce para o Cartão
A3: Autorizada | B3: 24.231.517/0001-50 | C3: SYS4B INFORMATICA LTDA | D3: Sys4B | E3: 61.198.164/0001-60 | F3: 45658 | G3: 2702 | H3: 45699 | I3: 24607.42 | J3: 22/12/24 a 21/01/25 | K3: 45759 | L3: INIBANK-54 | M3: Evoluções Salesforce para o Cartão
A4: Autorizada | B4: 24.231.517/0001-50 | C4: SYS4B INFORMATICA LTDA | D4: Sys4B | E4: 61.198.164/0001-60 | F4: 45689 | G4: 2753 | H4: 45727 | I4: 303490.65 | J4: 22/01/25 a 21/02/25 | K4: 45787 | L4: INIBANK-54 | M4: Evoluções Salesforce para o Cartão
A5: Autorizada | B5: 24.231.517/0001-50 | C5: SYS4B INFORMATICA LTDA | D5: Sys4B | E5: 61.198.164/0001-60 | F5: 45717 | G5: 2791 | H5: 45749 | I5: 212597.4 | J5: 22/02/25 a 21/03/25 | K5: 45809 | L5: INIBANK-54 | M5: Evoluções Salesforce para o Cartão
A6: Autorizada | B6: 24.231.517/0001-50 | C6: SYS4B INFORMATICA LTDA | D6: Sys4B | E6: 61.198.164/0001-60 | F6: 45748 | G6: 2838 | H6: 45783 | I6: 284824.47 | J6: 22/03/25 a 21/04/25 | K6: 45843 | L6: INIBANK-54 | M6: Evoluções Salesforce para o Cartão
A7: Cancelada | B7: 24.231.517/0001-50 | C7: SYS4B INFORMATICA LTDA | D7: Sys4B | E7: 61.198.164/0001-60 | F7: 45778 | G7: 2886 | H7: 45811 | I7: 32224 | J7: 22/04/25 a 21/05/25 | K7: 45871 | L7: INIBANK-54 | M7: Evoluções Salesforce para o Cartão
A8: Autorizada | B8: 24.231.517/0001-50 | C8: SYS4B INFORMATICA LTDA | D8: Sys4B | E8: 61.198.164/0001-60 | F8: 45778 | G8: 2887 | H8: 45811 | I8: 283830.3 | J8: 22/04/25 a 21/05/25 | K8: 45871 | L8: INIBANK-54 | M8: Evoluções Salesforce para o Cartão
A9: Autorizada | B9: 65.599.953/0001-63 | C9: CAPGEMINI BRASIL LTDA | D9: Capgemini | E9: 04.862.600/0001-10 | F9: 45658 | G9: 145286 | H9: 45701 | I9: 131897.28 | J9: 01/01/25 a 31/01/25 | K9: 45746 | L9: INIBANK-611 | M9: Implantação do SalesForce para Central de Atendimento de Clientes PJ
A10: Autorizada | B10: 65.599.953/0001-63 | C10: CAPGEMINI BRASIL LTDA | D10: Capgemini | E10: 04.862.600/0001-10 | F10: 45689 | G10: 145885 | H10: 45729 | I10: 88245.42 | J10: 01/02/25 a 28/02/25 | K10: 45774 | L10: INIBANK-611 | M10: Implantação do SalesForce para Central de Atendimento de Clientes PJ
A11: Autorizada | B11: 65.599.953/0001-63 | C11: CAPGEMINI BRASIL LTDA | D11: Capgemini | E11: 61.198.164/0001-60 | F11: 45717 | I11: 146501.52 | J11: 01/03/25 a 31/03/25 | L11: INIBANK-226 | M11: Evoluções e Melhorias
A12: Autorizada | B12: 65.599.953/0001-63 | C12: CAPGEMINI BRASIL LTDA | D12: Capgemini | E12: 04.862.600/0001-10 | F12: 45717 | I12: 101456.94 | J12: 01/03/25 a 31/03/25 | L12: INIBANK-611 | M12: Implantação do SalesForce para Central de Atendimento de Clientes PJ
A13: Autorizada | B13: 65.599.953/0001-63 | C13: CAPGEMINI BRASIL LTDA | D13: Capgemini | E13: 61.198.164/0001-60 | F13: 45748 | G13: 147368 | H13: 45789 | I13: 89693.94 | J13: 01/04/25 a 21/04/25 | K13: 45834 | L13: INIBANK-226 | M13: Evoluções e Melhorias
A14: Autorizada | B14: 65.599.953/0001-63 | C14: CAPGEMINI BRASIL LTDA | D14: Capgemini | E14: 04.862.600/0001-10 | F14: 45748 | G14: 147373 | H14: 45789 | I14: 77929.2 | J14: 01/04/25 a 21/04/25 | K14: 45834 | L14: INIBANK-611 | M14: Implantação do SalesForce para Central de Atendimento de Clientes PJ
A15: Autorizada | B15: 65.599.953/0001-63 | C15: CAPGEMINI BRASIL LTDA | D15: Capgemini | E15: 04.862.600/0001-10 | F15: 45778 | G15: 148462 | H15: 45819 | I15: 121633.02 | J15: 22/04/25 a 21/05/25 | K15: 45864 | L15: INIBANK-611 | M15: Implantação do SalesForce para Central de Atendimento de Clientes PJ
A16: Autorizada | B16: 65.599.953/0001-63 | C16: CAPGEMINI BRASIL LTDA | D16: Capgemini | E16: 61.198.164/0001-60 | F16: 45778 | G16: 148457 | H16: 45819 | I16: 200222.04 | J16: 22/04/25 a 21/05/25 | K16: 45864 | L16: INIBANK-226 | M16: Evoluções e Melhorias
A17: Autorizada | B17: 06.029.766/0004-28 | C17: OSF DIGITAL LTDA | D17: OSF Digital | E17: 04.862.600/0001-10 | F17: 45717 | G17: 763 | H17: 45755 | I17: 41333.04 | J17: 01/03/25 a 31/03/25 | K17: 45785 | L17: INIBANK-611 | M17: Implantação do SalesForce para Central de Atendimento de Clientes PJ
A18: Autorizada | B18: 06.029.766/0004-28 | C18: OSF DIGITAL LTDA | D18: OSF Digital | E18: 04.862.600/0001-10 | F18: 45778 | G18: 883 | H18: 45818 | I18: 38556 | J18: 22/04/25 a 21/05/25 | K18: 45848 | L18: INIBANK-611 | M18: Implantação do SalesForce para Central de Atendimento de Clientes PJ
A19: Autorizada | B19: 06.029.766/0004-28 | C19: OSF DIGITAL LTDA | D19: OSF Digital | E19: 04.862.600/0001-10 | F19: 45778 | G19: 884 | H19: 45818 | I19: 54864.69 | J19: 22/04/25 a 21/05/25 | K19: 45848 | L19: INIBANK-611 | M19: Implantação do SalesForce para Central de Atendimento de Clientes PJ
A20: Autorizada | B20: 65.599.953/0001-63 | C20: CAPGEMINI BRASIL LTDA | D20: Capgemini | E20: 04.862.600/0001-10 | F20: 45809 | G20: 149204 | H20: 45846 | I20: 115880.7 | J20: 22/05/25 a 21/06/25 | K20: 45891 | L20: INIBANK-611 | M20: Implantação do SalesForce para Central de Atendimento de Clientes PJ
A21: Autorizada | B21: 65.599.953/0001-63 | C21: CAPGEMINI BRASIL LTDA | D21: Capgemini | E21: 61.198.164/0001-60 | F21: 45809 | G21: 149200 | H21: 45846 | I21: 104949.36 | J21: 22/05/25 a 21/06/25 | K21: 45891
A22: Autorizada | B22: 65.599.953/0001-63 | C22: CAPGEMINI BRASIL LTDA | D22: Capgemini | E22: 61.198.164/0001-60 | F22: 45809 | G22: 149207 | H22: 45846 | I22: 52130.88 | J22: 22/05/25 a 21/06/25 | K22: 45891
A23: Autorizada | B23: 06.029.766/0004-28 | C23: OSF DIGITAL LTDA | D23: OSF Digital | E23: 04.862.600/0001-10 | F23: 45809 | G23: 959 | H23: 45849 | I23: 38556 | J23: 22/05/25 a 21/06/25 | K23: 45880 | L23: INIBANK-611 | M23: Implantação do SalesForce para Central de Atendimento de Clientes PJ
A24: Autorizada | B24: 06.029.766/0004-28 | C24: OSF DIGITAL LTDA | D24: OSF Digital | E24: 04.862.600/0001-10 | F24: 45809 | G24: 960 | H24: 45849 | I24: 41333.04 | J24: 22/05/25 a 21/06/25 | K24: 45880 | L24: INIBANK-611 | M24: Implantação do SalesForce para Central de Atendimento de Clientes PJ
A25: Autorizada | B25: 24.231.517/0001-50 | C25: SYS4B INFORMATICA LTDA | D25: Sys4B | E25: 04.862.600/0001-10 | F25: 45809 | G25: 2937 | H25: 45845 | I25: 297661.94 | J25: 22/05/25 a 21/06/25 | K25: 45905 | L25: INIBANK-611 | M25: Implantação do SalesForce para Central de Atendimento de Clientes PJ
A26: Autorizada | B26: 24.231.517/0001-50 | C26: SYS4B INFORMATICA LTDA | D26: Sys4B | E26: 61.198.164/0001-60 | F26: 45809 | G26: 2947 | H26: 45848 | I26: 31754.33 | J26: 22/05/25 a 21/06/25 | K26: 45908 | L26: INIBANK-1173 | M26: [Book] Squad Salesforce (Atendimento)
A27: Cancelada | B27: 65.599.953/0001-63 | C27: CAPGEMINI BRASIL LTDA | D27: Capgemini | E27: 04.862.600/0001-10 | F27: 45839 | G27: 149983 | H27: 45874 | I27: 87082.32 | J27: 22/06/25 a 21/07/25 | K27: 45919 | L27: INIBANK-611 | M27: Implantação do SalesForce para Central de Atendimento de Clientes PJ
A28: Autorizada | B28: 65.599.953/0001-63 | C28: CAPGEMINI BRASIL LTDA | D28: Capgemini | E28: 04.862.600/0001-10 | F28: 45839 | G28: 149984 | H28: 45874 | I28: 114058.86 | J28: 22/06/25 a 21/07/25 | K28: 45919 | L28: INIBANK-611 | M28: Implantação do SalesForce para Central de Atendimento de Clientes PJ
A29: Cancelada | B29: 65.599.953/0001-63 | C29: CAPGEMINI BRASIL LTDA | D29: Capgemini | E29: 61.198.164/0001-60 | F29: 45839 | G29: 149989 | H29: 45874 | I29: 46181.16 | J29: 22/06/25 a 21/07/25 | K29: 45919 | L29: INIBANK-1173 | M29: [Book] Squad Salesforce (Atendimento)
A30: Cancelada | B30: 06.029.766/0004-28 | C30: OSF DIGITAL LTDA | D30: OSF Digital | E30: 04.862.600/0001-10 | F30: 45839 | G30: 1023 | H30: 45876 | I30: 25704 | J30: 22/06/25 a 21/07/25 | K30: 45908 | L30: INIBANK-611 | M30: Implantação do SalesForce para Central de Atendimento de Clientes PJ
A31: Autorizada | B31: 24.231.517/0001-50 | C31: SYS4B INFORMATICA LTDA | D31: Sys4B | E31: 61.198.164/0001-60 | F31: 45839 | G31: 2978 | H31: 45874 | I31: 32224 | J31: 22/06/25 a 21/07/25 | K31: 45934 | L31: INIBANK-1173 | M31: [Book] Squad Salesforce (Atendimento)
A32: Cancelada | B32: 06.029.766/0004-28 | C32: OSF DIGITAL LTDA | D32: OSF Digital | E32: 04.862.600/0001-10 | F32: 45839 | G32: 1024 | H32: 45876 | I32: 11809.44 | J32: 22/06/25 a 21/07/25 | K32: 45908 | L32: INIBANK-611 | M32: Implantação do SalesForce para Central de Atendimento de Clientes PJ
A33: Cancelada | B33: 24.231.517/0001-50 | C33: SYS4B INFORMATICA LTDA | D33: Sys4B | E33: 61.198.164/0001-60 | F33: 45839 | G33: 2977 | H33: 45874 | I33: 276726.81 | J33: 22/06/25 a 21/07/25 | K33: 45934 | L33: INIBANK-1173 | M33: [Book] Squad Salesforce (Atendimento)
A34: Autorizada | B34: 06.029.766/0004-28 | C34: OSF DIGITAL LTDA | D34: OSF Digital | E34: 04.862.600/0001-10 | F34: 45839 | G34: 1043 | H34: 45883 | I34: 37513.44 | J34: 22/06/25 a 21/07/25 | K34: 45908 | L34: INIBANK-611 | M34: Implantação do SalesForce para Central de Atendimento de Clientes PJ
... A137: Autorizada | B137: 24.231.517/0001-50 | C137: SYS4B INFORMATICA LTDA | D137: Sys4B | E137: 61.198.164/0001-60 | F137: 46054 | G137: 3297 | H137: 46085 | I137: 126477.51 | J137: 22/01/25 a 21/02/26 | K137: 46131 | L137: INIBANK-1417 | M137: [Sustentação] Atendimento / Salesforce

Sheet NOTA_FISCAL_ANALITICO
A1: CNPJ_PRESTADOR | B1: RAZAO_SOCIAL | C1: NOME_FANTASIA | D1: COMPETENCIA | E1: NFE | F1: DATA_EMISSAO | G1: SUBTOTAL_NFE | H1: APURACAO | I1: DATA_VENCIMENTO | J1: INICIATIVA | K1: MATRICULA | L1: NOME_PROFISSIONAL | M1: PAPEL_PRESTADOR | N1: TOTAL_HORAS | O1: HH
A2: 24.231.517/0001-50 | B2: SYS4B INFORMATICA LTDA | C2: Sys4B | D2: 45658 | E2: 2701 | F2: 45699 | G2: 191611.98 | H2: 22/12/24 a 21/01/25 | I2: 45759 | J2: INIBANK-54 | L2: - | N2: 0 | O2: 0
A3: 24.231.517/0001-50 | B3: SYS4B INFORMATICA LTDA | C3: Sys4B | D3: 45658 | E3: 2702 | F3: 45699 | G3: 24607.42 | H3: 22/12/24 a 21/01/25 | I3: 45759 | J3: INIBANK-54 | L3: - | N3: 0 | O3: 0
A4: 65.599.953/0001-63 | B4: CAPGEMINI BRASIL LTDA | C4: Capgemini | D4: 45658 | E4: 145286 | F4: 45701 | G4: 65948.64 | H4: 22/12/24 a 21/01/25 | I4: 45746 | J4: INIBANK-611 | L4: - | N4: 0 | O4: 0
A5: 65.599.953/0001-63 | B5: CAPGEMINI BRASIL LTDA | C5: Capgemini | D5: 45658 | E5: 145286 | F5: 45701 | G5: 65948.64 | H5: 22/12/24 a 21/01/25 | I5: 45746 | J5: INIBANK-226 | L5: - | N5: 0 | O5: 0
A6: 24.231.517/0001-50 | B6: SYS4B INFORMATICA LTDA | C6: Sys4B | D6: 45689 | E6: 2753 | F6: 45727 | G6: 151745.33 | H6: 22/01/25 a 21/02/25 | I6: 45787 | J6: INIBANK-54 | L6: - | N6: 0 | O6: 0
A7: 24.231.517/0001-50 | B7: SYS4B INFORMATICA LTDA | C7: Sys4B | D7: 45689 | E7: 2753 | F7: 45727 | G7: 151745.33 | H7: 22/01/25 a 21/02/25 | I7: 45787 | J7: INIBANK-225 | L7: - | N7: 0 | O7: 0
A8: 65.599.953/0001-63 | B8: CAPGEMINI BRASIL LTDA | C8: Capgemini | D8: 45689 | E8: 145885 | F8: 45729 | G8: 9928.38 | H8: 22/01/25 a 21/02/25 | I8: 45774 | J8: INIBANK-611 | L8: SAMUEL PEREIRA JUNIOR | M8: Desenvolvedor Salesforce Sênior | N8: 49 | O8: 202.62
A9: 65.599.953/0001-63 | B9: CAPGEMINI BRASIL LTDA | C9: Capgemini | D9: 45689 | E9: 145885 | F9: 45729 | G9: 32419.2 | H9: 22/01/25 a 21/02/25 | I9: 45774 | J9: INIBANK-611 | K9: P0661715 | L9: MARCEL VALLIM MOREIRA | M9: Desenvolvedor Salesforce Sênior | N9: 160 | O9: 202.62
A10: 65.599.953/0001-63 | B10: CAPGEMINI BRASIL LTDA | C10: Capgemini | D10: 45689 | E10: 145885 | F10: 45729 | G10: 45897.84 | H10: 22/01/25 a 21/02/25 | I10: 45774 | J10: INIBANK-611 | K10: P0661361 | L10: FERNANDO DA SILVA TREVISAN | M10: Tech Lead Salesforce | N10: 162 | O10: 283.32
A11: 24.231.517/0001-50 | B11: SYS4B INFORMATICA LTDA | C11: Sys4B | D11: 45717 | E11: 2791 | F11: 45749 | G11: 17161.46 | H11: 22/02/25 a 21/03/25 | I11: 45809 | J11: INIBANK-54 | K11: P0650648 | L11: Lucas Takita | M11: Desenvolvedor Salesforce Sênior | N11: 82.25 | O11: 208.65
A12: 24.231.517/0001-50 | B12: SYS4B INFORMATICA LTDA | C12: Sys4B | D12: 45717 | E12: 2791 | F12: 45749 | G12: 15022.8 | H12: 22/02/25 a 21/03/25 | I12: 45809 | J12: INIBANK-54 | K12: P0651731 | L12: Fernando Piovezan | M12: Desenvolvedor Salesforce Sênior | N12: 72 | O12: 208.65
A13: 24.231.517/0001-50 | B13: SYS4B INFORMATICA LTDA | C13: Sys4B | D13: 45717 | E13: 2791 | F13: 45749 | G13: 14188.2 | H13: 22/02/25 a 21/03/25 | I13: 45809 | J13: INIBANK-54 | K13: P0661870 | L13: Gustavo Siqueira Martins | M13: Desenvolvedor Salesforce Sênior | N13: 68 | O13: 208.65
A14: 24.231.517/0001-50 | B14: SYS4B INFORMATICA LTDA | C14: Sys4B | D14: 45717 | E14: 2791 | F14: 45749 | G14: 14605.5 | H14: 22/02/25 a 21/03/25 | I14: 45809 | J14: INIBANK-54 | K14: P0654694 | L14: Carlos Eduardo Santos Santana | M14: Desenvolvedor Salesforce Sênior | N14: 70 | O14: 208.65
A15: 24.231.517/0001-50 | B15: SYS4B INFORMATICA LTDA | C15: Sys4B | D15: 45717 | E15: 2791 | F15: 45749 | G15: 16223.25 | H15: 22/02/25 a 21/03/25 | I15: 45809 | J15: INIBANK-54 | K15: P0660057 | L15: Cleiton Lima de Jesus | M15: Desenvolvedor Salesforce Sênior | N15: 72.75 | O15: 223
A16: 24.231.517/0001-50 | B16: SYS4B INFORMATICA LTDA | C16: Sys4B | D16: 45717 | E16: 2791 | F16: 45749 | G16: 15610 | H16: 22/02/25 a 21/03/25 | I16: 45809 | J16: INIBANK-54 | K16: P0656797 | L16: Gustavo Seiji Onizuka | M16: Desenvolvedor Salesforce | N16: 70 | O16: 223
A17: 24.231.517/0001-50 | B17: SYS4B INFORMATICA LTDA | C17: Sys4B | D17: 45717 | E17: 2791 | F17: 45749 | G17: 15283.61 | H17: 22/02/25 a 21/03/25 | I17: 45809 | J17: INIBANK-54 | K17: P0662312 | L17: Francielle Thiezo Revesso Pinto | M17: Administrador Salesforce | N17: 73.25 | O17: 208.65
A18: 24.231.517/0001-50 | B18: SYS4B INFORMATICA LTDA | C18: Sys4B | D18: 45717 | E18: 2791 | F18: 45749 | G18: 14709.83 | H18: 22/02/25 a 21/03/25 | I18: 45809 | J18: INIBANK-54 | K18: P0658519 | L18: Leonardo Lins | M18: Desenvolvedor Salesforce Sênior | N18: 70.5 | O18: 208.65
A19: 24.231.517/0001-50 | B19: SYS4B INFORMATICA LTDA | C19: Sys4B | D19: 45717 | E19: 2791 | F19: 45749 | G19: 3110 | H19: 22/02/25 a 21/03/25 | I19: 45809 | J19: INIBANK-54 | K19: P0000000 | L19: Plantão Salesforce Odin | M19: Desenvolvedor Salesforce Sênior | N19: 0 | O19: 0
A20: 24.231.517/0001-50 | B20: SYS4B INFORMATICA LTDA | C20: Sys4B | D20: 45717 | E20: 2791 | F20: 45749 | G20: -19615.95 | H20: 22/02/25 a 21/03/25 | I20: 45809 | J20: INIBANK-54 | L20: Desconto 3/3 | N20: 0 | O20: 0
A21: 24.231.517/0001-50 | B21: SYS4B INFORMATICA LTDA | C21: Sys4B | D21: 45717 | E21: 2791 | F21: 45749 | G21: 17161.46 | H21: 22/02/25 a 21/03/25 | I21: 45809 | J21: INIBANK-225 | K21: P0650648 | L21: Lucas Takita | M21: Desenvolvedor Salesforce Sênior | N21: 82.25 | O21: 208.65
A22: 24.231.517/0001-50 | B22: SYS4B INFORMATICA LTDA | C22: Sys4B | D22: 45717 | E22: 2791 | F22: 45749 | G22: 15022.8 | H22: 22/02/25 a 21/03/25 | I22: 45809 | J22: INIBANK-225 | K22: P0651731 | L22: Fernando Piovezan | M22: Desenvolvedor Salesforce Sênior | N22: 72 | O22: 208.65
A23: 24.231.517/0001-50 | B23: SYS4B INFORMATICA LTDA | C23: Sys4B | D23: 45717 | E23: 2791 | F23: 45749 | G23: 14188.2 | H23: 22/02/25 a 21/03/25 | I23: 45809 | J23: INIBANK-225 | K23: P0661870 | L23: Gustavo Siqueira Martins | M23: Desenvolvedor Salesforce Sênior | N23: 68 | O23: 208.65
A24: 24.231.517/0001-50 | B24: SYS4B INFORMATICA LTDA | C24: Sys4B | D24: 45717 | E24: 2791 | F24: 45749 | G24: 14605.5 | H24: 22/02/25 a 21/03/25 | I24: 45809 | J24: INIBANK-225 | K24: P0654694 | L24: Carlos Eduardo Santos Santana | M24: Desenvolvedor Salesforce Sênior | N24: 70 | O24: 208.65
A25: 24.231.517/0001-50 | B25: SYS4B INFORMATICA LTDA | C25: Sys4B | D25: 45717 | E25: 2791 | F25: 45749 | G25: 16223.25 | H25: 22/02/25 a 21/03/25 | I25: 45809 | J25: INIBANK-225 | K25: P0660057 | L25: Cleiton Lima de Jesus | M25: Desenvolvedor Salesforce Sênior | N25: 72.75 | O25: 223
A26: 24.231.517/0001-50 | B26: SYS4B INFORMATICA LTDA | C26: Sys4B | D26: 45717 | E26: 2791 | F26: 45749 | G26: 15610 | H26: 22/02/25 a 21/03/25 | I26: 45809 | J26: INIBANK-225 | K26: P0656797 | L26: Gustavo Seiji Onizuka | M26: Desenvolvedor Salesforce | N26: 70 | O26: 223
A27: 24.231.517/0001-50 | B27: SYS4B INFORMATICA LTDA | C27: Sys4B | D27: 45717 | E27: 2791 | F27: 45749 | G27: 15283.61 | H27: 22/02/25 a 21/03/25 | I27: 45809 | J27: INIBANK-225 | K27: P0662312 | L27: Francielle Thiezo Revesso Pinto | M27: Administrador Salesforce | N27: 73.25 | O27: 208.65
A28: 24.231.517/0001-50 | B28: SYS4B INFORMATICA LTDA | C28: Sys4B | D28: 45717 | E28: 2791 | F28: 45749 | G28: 14709.83 | H28: 22/02/25 a 21/03/25 | I28: 45809 | J28: INIBANK-225 | K28: P0658519 | L28: Leonardo Lins | M28: Desenvolvedor Salesforce Sênior | N28: 70.5 | O28: 208.65
A29: 24.231.517/0001-50 | B29: SYS4B INFORMATICA LTDA | C29: Sys4B | D29: 45717 | E29: 2791 | F29: 45749 | G29: 3110 | H29: 22/02/25 a 21/03/25 | I29: 45809 | J29: INIBANK-225 | K29: P0000000 | L29: Plantão Salesforce Odin | M29: Desenvolvedor Salesforce Sênior | N29: 0 | O29: 0
A30: 24.231.517/0001-50 | B30: SYS4B INFORMATICA LTDA | C30: Sys4B | D30: 45717 | E30: 2791 | F30: 45749 | G30: -19615.95 | H30: 22/02/25 a 21/03/25 | I30: 45809 | J30: INIBANK-225 | L30: Desconto 3/3 | N30: 0 | O30: 0
A31: 65.599.953/0001-63 | B31: CAPGEMINI BRASIL LTDA | C31: Capgemini | D31: 45717 | G31: 21815.64 | H31: 22/02/25 a 21/03/25 | J31: INIBANK-226 | K31: P0659788 | L31: RAPHAEL ROSA DE BARROS | M31: Tech Lead Salesforce | N31: 77 | O31: 283.32
A32: 65.599.953/0001-63 | B32: CAPGEMINI BRASIL LTDA | C32: Capgemini | D32: 45717 | G32: 11332.8 | H32: 22/02/25 a 21/03/25 | J32: INIBANK-226 | K32: P0659789 | L32: GUSTAVO COSTA TENORIO | M32: Arquiteto Especialista Salesforce | N32: 40 | O32: 283.32
A33: 65.599.953/0001-63 | B33: CAPGEMINI BRASIL LTDA | C33: Capgemini | D33: 45717 | G33: 42252.96 | H33: 22/02/25 a 21/03/25 | J33: INIBANK-226 | K33: P0659891 | L33: MARIIA NIKONOVA | M33: Desenvolvedor Salesforce Sênior | N33: 164 | O33: 257.64
A34: 65.599.953/0001-63 | B34: CAPGEMINI BRASIL LTDA | C34: Capgemini | D34: 45717 | G34: 40707.12 | H34: 22/02/25 a 21/03/25 | J34: INIBANK-226 | K34: P0659884 | L34: VICTOR BERNARDES ARAUJO | M34: Desenvolvedor Salesforce Sênior | N34: 158 | O34: 257.64
A35: 65.599.953/0001-63 | B35: CAPGEMINI BRASIL LTDA | C35: Capgemini | D35: 45717 | G35: 30393 | H35: 22/02/25 a 21/03/25 | J35: INIBANK-226 | K35: P0654808 | L35: Nivaldo Estevao da Silva Junior | M35: Desenvolvedor Pleno | N35: 150 | O35: 202.62
A36: 65.599.953/0001-63 | B36: CAPGEMINI BRASIL LTDA | C36: Capgemini | D36: 45717 | G36: 13778.16 | H36: 22/02/25 a 21/03/25 | J36: INIBANK-611 | L36: SAMUEL PEREIRA JUNIOR | M36: Desenvolvedor Salesforce Sênior | N36: 68 | O36: 202.62
A37: 65.599.953/0001-63 | B37: CAPGEMINI BRASIL LTDA | C37: Capgemini | D37: 45717 | G37: 9725.76 | H37: 22/02/25 a 21/03/25 | J37: INIBANK-611 | K37: P0663000 | L37: DIEGO FELIPE SOUZA OLIVEIRA | M37: Desenvolvedor Salesforce Sênior | N37: 48 | O37: 202.62
A38: 65.599.953/0001-63 | B38: CAPGEMINI BRASIL LTDA | C38: Capgemini | D38: 45717 | G38: 32621.82 | H38: 22/02/25 a 21/03/25 | J38: INIBANK-611 | K38: P0661715 | L38: MARCEL VALLIM MOREIRA | M38: Desenvolvedor Salesforce Sênior | N38: 161 | O38: 202.62
A39: 65.599.953/0001-63 | B39: CAPGEMINI BRASIL LTDA | C39: Capgemini | D39: 45717 | G39: 45331.2 | H39: 22/02/25 a 21/03/25 | J39: INIBANK-611 | K39: P0661361 | L39: FERNANDO DA SILVA TREVISAN | M39: Tech Lead Salesforce | N39: 160 | O39: 283.32
A40: 06.029.766/0004-28 | B40: OSF DIGITAL LTDA | C40: OSF Digital | D40: 45717 | E40: 763 | F40: 45755 | G40: 41333.04 | H40: 22/02/25 a 21/03/25 | I40: 45785 | J40: INIBANK-611 | K40: P0660856 | L40: Paulo Henrique Alves Pereira | M40: Desenvolvedor Salesforce Junior | N40: 168 | O40: 246.03
...

Sheet PRESTADOR
A1: MATRICULA | B1: STATUS_PRESTADOR | C1: NOME_PROFISSIONAL | D1: E-MAIL_PORTO | E1: E-MAIL_CONSULTORIA | F1: PAPEL_PRESTADOR | G1: NOME_FANTASIA | H1: INICIATIVA | I1: TIME | J1: HH | K1: ESTIMADO_MENSAL | L1: ESTIMADO_ANUAL
A2: P0659788 | B2: Inativo | C2: Raphael Rosa de Barros | D2: raphael.barros@portoseguro.com.br | E2: raphael.barros@capgemini.com | F2: Tech Lead Salesforce | G2: Capgemini | H2: INIBANK-1173 | I2: Evoluções e Melhorias | J2: 283.32 | K2: 49864.32 | L2: 548507.52
A3: P0659884 | B3: Inativo | C3: Victor Bernardes Araujo | D3: victor.araujo@portoseguro.com.br | E3: victor.b.araujo@capgemini.com | F3: Desenvolvedor Salesforce Sênior | G3: Capgemini | H3: INIBANK-1173 | I3: Evoluções e Melhorias | J3: 257.64 | K3: 45344.64 | L3: 498791.04
A4: P0661738 | B4: Ativo | C4: Erick Delfino Silva | D4: erick.delfino@portoseguro.com.br | E4: erick.silva@capgemini.com | F4: Analista de Teste Sênior | G4: Capgemini | H4: INIBANK-1173 | I4: Evoluções e Melhorias | J4: 193.74 | K4: 34098.24 | L4: 375080.64
A5: P0661166 | B5: Inativo | C5: Adejailson Antonio De Luna | D5: adejailson.luna@portoseguro.com.br | E5: adejailson.luna@meta.com.br | F5: Product Owner | G5: Meta | H5: INIBANK-1173 | I5: Evoluções e Melhorias | J5: 192.88 | K5: 33946.88 | L5: 373415.68
A6: P0660057 | B6: Ativo | C6: Cleiton Lima de Jesus | D6: cleiton.jesus@portoseguro.com.br | E6: cleiton.jesus@sys4b.com.br | F6: Desenvolvedor Salesforce Sênior | G6: Sys4B | H6: INIBANK-1173 | I6: Evoluções e Melhorias | J6: 228.58 | K6: 40230.08 | L6: 442530.88
A7: P0656797 | B7: Ativo | C7: Gustavo Seiji Onizuka | D7: gustavo.onizuka@portoseguro.com.br | E7: gustavo.s.onizuka@sys4b.com.br | F7: Desenvolvedor Salesforce | G7: Sys4B | H7: INIBANK-1173 | I7: Evoluções e Melhorias | J7: 213.87 | K7: 37641.12 | L7: 414052.32
A8: P0658519 | B8: Ativo | C8: Leonardo Lins | D8: leonardo.lins@portoseguro.com.br | E8: leonardo.silva@sys4b.com.br | F8: Desenvolvedor Salesforce Sênior | G8: Sys4B | H8: INIBANK-1173 | I8: Evoluções e Melhorias | J8: 213.87 | K8: 37641.12 | L8: 414052.32
A9: P0662282 | B9: Inativo | C9: Joyce Andrade | D9: joyce.barretosouza@portoseguro.com.br | E9: joyce.souza@sys4b.com.br | F9: Consultor UX/UI | G9: Sys4B | H9: INIBANK-1173 | I9: Evoluções e Melhorias | J9: 201.4 | K9: 35446.4 | L9: 389910.4
A10: P0661574 | B10: Ativo | C10: Leonardo Lassance | D10: leonardo.lassance@portoseguro.com.br | E10: leonardo.lassance@capgemini.com | F10: Project Manager | G10: Capgemini | H10: INIBANK-1173 | I10: Evoluções e Melhorias | J10: 299.76 | K10: 52757.76 | L10: 580335.36
A11: P0659891 | B11: Inativo | C11: Mariia Nikonova | D11: mariia.nikonova@portoseguro.com.br | E11: mariia.nikonova@capgemini.com | F11: Desenvolvedor Salesforce Sênior | G11: Capgemini | H11: INIBANK-611 | I11: Novos Projetos | J11: 257.64 | K11: 45344.64 | L11: 498791.04
A12: P0661361 | B12: Ativo | C12: Fernando da Silva Trevisan | D12: fernando.trevisan@portoseguro.com.br | E12: fernando.trevisan@capgemini.com | F12: Tech Lead Salesforce | G12: Capgemini | H12: INIBANK-1173 | I12: Evoluções e Melhorias | J12: 289.35 | K12: 50925.6 | L12: 560181.6
A13: P0661715 | B13: Ativo | C13: Marcel Vallim Moreira | D13: marcel.moreira@portoseguro.com.br | E13: marcel.moreira@capgemini.com | F13: Desenvolvedor Salesforce Sênior | G13: Capgemini | H13: INIBANK-1173 | I13: Evoluções e Melhorias | J13: 202.62 | K13: 35661.12 | L13: 392272.32
... A15: P0659790 | B15: Inativo | C15: Rafael Lucateles Cruz | D15: rafael.lucateles@portoseguro.com.br | E15: rafael.a.cruz@capgemini.com | F15: Consultor UX/UI Sênior | G15: Capgemini | H15: INIBANK-611 | I15: Novos Projetos | J15: 222.09 | K15: 39087.84 | L15: 429966.24
A16: P0659934 | B16: Inativo | C16: Jorge Cardoso Filho | D16: jorge.filho@portoseguro.com.br | F16: Analista de Teste | G16: GFT | H16: INIBANK-611 | I16: Novos Projetos | J16: 184.6 | K16: 32489.6 | L16: 357385.6
A17: P0654694 | B17: Ativo | C17: Carlos Eduardo Santos Santana | D17: carloseduardo.santos@portoseguro.com.br | E17: carlos.santana@sys4b.com.br | F17: Desenvolvedor Salesforce Sênior | G17: Sys4B | H17: INIBANK-1173 | I17: Evoluções e Melhorias | J17: 213.87 | K17: 37641.12 | L17: 414052.32
A18: P0662312 | B18: Ativo | C18: Francielle Thiezo Revesso Pinto | D18: francielle.pinto@portoseguro.com.br | E18: francielle.revesso@sys4b.com.br | F18: Administrador Salesforce | G18: Sys4B | H18: INIBANK-1417 | I18: Plataforma Salesforce Odin | J18: 213.87 | K18: 37641.12 | L18: 414052.32
A19: P0650648 | B19: Ativo | C19: Lucas Takita | D19: lucas.takita@portoseguro.com.br | E19: lucas.takita@infinitysys.com.br | F19: Desenvolvedor Salesforce Sênior | G19: Sys4B | H19: INIBANK-1417 | I19: Plataforma Salesforce Odin | J19: 213.87 | K19: 37641.12 | L19: 414052.32
A20: P0663654 | B20: Ativo | C20: Gabriel Costa Datovo Inoue Maekawa | D20: gabriel.maekawa@portoseguro.com.br | E20: gabriel.montalbini@sys4b.com.br | F20: Desenvolvedor Pleno | G20: Sys4B | H20: INIBANK-1417 | I20: Plataforma Salesforce Odin | J20: 191.36 | K20: 33679.36 | L20: 370472.96
A21: P0000000 | B21: Ativo | C21: Plantão Salesforce Odin | F21: Desenvolvedor Salesforce Sênior | G21: Sys4B | H21: INIBANK-1417 | I21: Plataforma Salesforce Odin | J21: 213.87 | K21: 40000 | L21: 480000

Sheet FORECAST
A1: INICIATIVA | B1: INICIATIVA_DESCRICAO | C1: INICIATIVA_TIPO | D1: INICIATIVA_DIREÇÃO | E1: TOTAL_FORECAST | F1: 46023 | G1: 46054 | H1: 46082 | I1: 46113 | J1: 46143 | K1: 46174 | L1: 46204 | M1: 46235 | N1: 46266 | O1: 46296 | P1: 46327 | Q1: 46357
A2: INIBANK-54 | B2: Evoluções Salesforce para o Cartão | C2: Forecast | D2: Soma | E2: =SUM(F2:Q2) -> 0 | F2: 0 | G2: 0 | H2: 0 | I2: 0 | J2: 0 | K2: 0 | L2: 0 | M2: 0 | N2: 0 | O2: 0 | P2: 0 | Q2: 0
A3: INIBANK-226 | B3: Evoluções e Melhorias | C3: Forecast | D3: Soma | E3: =SUM(F3:Q3) -> 0 | F3: 0 | G3: 0 | H3: 0 | I3: 0 | J3: 0 | K3: 0 | L3: 0 | M3: 0 | N3: 0 | O3: 0 | P3: 0 | Q3: 0
A4: INIBANK-611 | B4: Implantação do SalesForce para Central de Atendimento de Clientes PJ | C4: Forecast | D4: Soma | E4: =SUM(F4:Q4) -> 0 | F4: 0 | G4: 0 | H4: 0 | I4: 0 | J4: 0 | K4: 0 | L4: 0 | M4: 0 | N4: 0 | O4: 0 | P4: 0 | Q4: 0
A5: INIBANK-289 | B5: Sustentação Atendimento Salesforce Odin | C5: Forecast | D5: Soma | E5: =SUM(F5:Q5) -> 0 | F5: 0 | G5: 0 | H5: 0 | I5: 0 | J5: 0 | K5: 0 | L5: 0 | M5: 0 | N5: 0 | O5: 0 | P5: 0 | Q5: 0
A6: INIBANK-1417 | B6: [Sustentação] Atendimento / Salesforce | C6: Forecast | D6: Soma | E6: =SUM(F6:Q6) -> 1865718 | F6: 155476.5 | G6: 155476.5 | H6: 155476.5 | I6: 155476.5 | J6: 155476.5 | K6: 155476.5 | L6: 155476.5 | M6: 155476.5 | N6: 155476.5 | O6: 155476.5 | P6: 155476.5 | Q6: 155476.5
A7: INIBANK-1173 | B7: [Book] Squad Salesforce (Atendimento) | C7: Forecast | D7: Soma | E7: =SUM(F7:Q7) -> 3955366 | F7: 329613.83 | G7: 329613.83 | H7: 329613.83 | I7: 329613.83 | J7: 329613.83 | K7: 329613.83 | L7: 329613.83 | M7: 329613.83 | N7: 329613.83 | O7: 329613.83 | P7: 329613.83 | Q7: 329613.83
A8: INIBANK-1173 | B8: [Book] Squad Salesforce (Atendimento) - Adicional Postergação NF 2025/2026 | C8: Adicional Forecast | D8: Soma | E8: =SUM(F8:Q8) -> 196499 | F8: 196499 | G8: 0 | H8: 0 | I8: 0 | J8: 0 | K8: 0 | L8: 0 | M8: 0 | N8: 0 | O8: 0 | P8: 0 | Q8: 0
A9: INIBANK-1349 | B9: Atendimento INVEST BANK - MVP | C9: Forecast | D9: Soma | E9: =SUM(F9:Q9) -> 100000 | F9: 100000 | G9: 0 | H9: 0 | I9: 0 | J9: 0 | K9: 0 | L9: 0 | M9: 0 | N9: 0 | O9: 0 | P9: 0 | Q9: 0
A10: INIBANK-1349 | B10: Atendimento INVEST BANK - SAC + SEGMENTACÃO + PERMISSIONAMENTO | C10: Adicional Forecast | D10: Soma | E10: =SUM(F10:Q10) -> 90000 | F10: 0 | G10: 0 | H10: 45000 | I10: 45000 | J10: 0 | K10: 0 | L10: 0 | M10: 0 | N10: 0 | O10: 0 | P10: 0 | Q10: 0
A11: INIBANK-1173 | B11: [Book] Squad Salesforce (Atendimento) | C11: Redução Forecast | D11: Subtrai | E11: =SUM(F11:Q11) -> 2400000 | F11: 0 | G11: 0 | H11: 0 | I11: 0 | J11: 300000 | K11: 300000 | L11: 300000 | M11: 300000 | N11: 300000 | O11: 300000 | P11: 300000 | Q11: 300000

Sheet HISTOGRAMA
A1: MATRICULA | B1: STATUS_PRESTADOR | C1: NOME_PROFISSIONAL | D1: PAPEL_PRESTADOR | E1: NOME_FANTASIA | F1: INICIATIVA | G1: TIME | H1: HH | I1: ESTIMADO_MENSAL | J1: ESTIMADO_ANUAL | K1: 46023 | L1: 46054 | M1: 46082 | N1: 46113 | O1: 46143 | P1: 46174 | Q1: 46204 | R1: 46235 | S1: 46266 | T1: 46296 | U1: 46327 | V1: 46357
A2: P0659788 | B2: Inativo | C2: Raphael Rosa de Barros | D2: Tech Lead Salesforce | E2: Capgemini | F2: INIBANK-1173 | G2: Evoluções e Melhorias | H2: 283.32 | I2: =H2*176 -> 49864.32 | J2: =I2*11 -> 548507.52 | K2: 0 | L2: 0 | M2: 0 | N2: 0 | O2: 0 | P2: 0 | Q2: 0 | R2: 0 | S2: 0 | T2: 0 | U2: 0 | V2: 0
A3: P0659884 | B3: Inativo | C3: Victor Bernardes Araujo | D3: Desenvolvedor Salesforce Sênior | E3: Capgemini | F3: INIBANK-1173 | G3: Evoluções e Melhorias | H3: 257.64 | I3: =H3*176 -> 45344.64 | J3: =I3*11 -> 498791.04 | K3: 0 | L3: 0 | M3: 0 | N3: 0 | O3: 0 | P3: 0 | Q3: 0 | R3: 0 | S3: 0 | T3: 0 | U3: 0 | V3: 0
A4: P0661738 | B4: Ativo | C4: Erick Delfino Silva | D4: Analista de Teste Sênior | E4: Capgemini | F4: INIBANK-1173 | G4: Evoluções e Melhorias | H4: 193.74 | I4: =H4*176 -> 34098.24 | J4: =I4*11 -> 375080.64 | K4: 1 | L4: 1 | M4: 1 | N4: 0.5 | O4: 0 | P4: 0 | Q4: 0 | R4: 0 | S4: 0 | T4: 0 | U4: 0 | V4: 0
A5: P0661166 | B5: Inativo | C5: Adejailson Antonio De Luna | D5: Product Owner | E5: Meta | F5: INIBANK-1173 | G5: Evoluções e Melhorias | H5: 192.88 | I5: =H5*176 -> 33946.88 | J5: =I5*11 -> 373415.68 | K5: 0 | L5: 0 | M5: 0 | N5: 0 | O5: 0 | P5: 0 | Q5: 0 | R5: 0 | S5: 0 | T5: 0 | U5: 0 | V5: 0
A6: P0660057 | B6: Ativo | C6: Cleiton Lima de Jesus | D6: Desenvolvedor Salesforce Sênior | E6: Sys4B | F6: INIBANK-1173 | G6: Evoluções e Melhorias | H6: 228.58 | I6: =H6*176 -> 40230.08 | J6: =I6*11 -> 442530.88 | K6: 1 | L6: 1 | M6: 1 | N6: 1 | O6: 1 | P6: 1 | Q6: 1 | R6: 1 | S6: 1 | T6: 1 | U6: 1 | V6: 1
A7: P0656797 | B7: Ativo | C7: Gustavo Seiji Onizuka | D7: Desenvolvedor Salesforce | E7: Sys4B | F7: INIBANK-1173 | G7: Evoluções e Melhorias | H7: 213.87 | I7: =H7*176 -> 37641.12 | J7: =I7*11 -> 414052.32 | K7: 1 | L7: 1 | M7: 1 | N7: 0.5 | O7: 0 | P7: 0 | Q7: 0 | R7: 0 | S7: 0 | T7: 0 | U7: 0 | V7: 0
A8: P0658519 | B8: Ativo | C8: Leonardo Lins | D8: Desenvolvedor Salesforce Sênior | E8: Sys4B | F8: INIBANK-1173 | G8: Evoluções e Melhorias | H8: 213.87 | I8: =H8*176 -> 37641.12 | J8: =I8*11 -> 414052.32 | K8: 1 | L8: 1 | M8: 1 | N8: 1 | O8: 1 | P8: 1 | Q8: 1 | R8: 1 | S8: 1 | T8: 1 | U8: 1 | V8: 1
A9: P0662282 | B9: Inativo | C9: Joyce Andrade | D9: Consultor UX/UI | E9: Sys4B | F9: INIBANK-1173 | G9: Evoluções e Melhorias | H9: 201.4 | I9: =H9*176 -> 35446.4 | J9: =I9*11 -> 389910.4 | K9: 0 | L9: 0 | M9: 0 | N9: 0 | O9: 0 | P9: 0 | Q9: 0 | R9: 0 | S9: 0 | T9: 0 | U9: 0 | V9: 0
A10: P0661574 | B10: Ativo | C10: Leonardo Lassance | D10: Project Manager | E10: Capgemini | F10: INIBANK-1173 | G10: Evoluções e Melhorias | H10: 299.76 | I10: =H10*176 -> 52757.76 | J10: =I10*11 -> 580335.36 | K10: 1 | L10: 1 | M10: 1 | N10: 0.5 | O10: 0 | P10: 0 | Q10: 0 | R10: 0 | S10: 0 | T10: 0 | U10: 0 | V10: 0
A11: P0659891 | B11: Inativo | C11: Mariia Nikonova | D11: Desenvolvedor Salesforce Sênior | E11: Capgemini | F11: INIBANK-611 | G11: Novos Projetos | H11: 257.64 | I11: =H11*176 -> 45344.64 | J11: =I11*11 -> 498791.04 | K11: 0 | L11: 0 | M11: 0 | N11: 0 | O11: 0 | P11: 0 | Q11: 0 | R11: 0 | S11: 0 | T11: 0 | U11: 0 | V11: 0
A12: P0661361 | B12: Ativo | C12: Fernando da Silva Trevisan | D12: Tech Lead Salesforce | E12: Capgemini | F12: INIBANK-1173 | G12: Evoluções e Melhorias | H12: 289.35 | I12: =H12*176 -> 50925.6 | J12: =I12*11 -> 560181.6 | K12: 1 | L12: 1 | M12: 1 | N12: 0.5 | O12: 0 | P12: 0 | Q12: 0 | R12: 0 | S12: 0 | T12: 0 | U12: 0 | V12: 0
